<?xml version="1.0"?>
<robot xmlns:xacro="http://www.ros.org/wiki/xacro">
  <xacro:macro name="robot" params="prefix">
    <link
      name="${prefix}base_link">
      <inertial>
        <origin
          xyz="-0.0152000946909854 0.00117474039315474 0.0910195561515633"
          rpy="0 0 0" />
        <mass
          value="64.5439245165624" />
        <inertia
          ixx="1.49121577423484"
          ixy="-0.000190337575366599"
          ixz="0.0394039846606287"
          iyy="3.87052073855067"
          iyz="0.000421606962278842"
          izz="5.03992806522733" />
      </inertial>
      <visual>
        <origin
          xyz="0 0 0"
          rpy="0 0 0" />
        <geometry>
          <mesh
            filename="package://two_wheel_mr/meshes/base_link.STL" />
        </geometry>
        <material
          name="">
          <color
            rgba="1 1 1 1" />
        </material>
      </visual>
      <collision>
        <origin
          xyz="0 0 0"
          rpy="0 0 0" />
        <geometry>
          <mesh
            filename="package://two_wheel_mr/meshes/base_link.STL" />
        </geometry>
      </collision>
    </link>

    <!-- <link name="${prefix}base_footprint" />

    <joint name="${prefix}base_joint" type="fixed">
      <parent link="${prefix}base_footprint" />
      <child link="${prefix}base_link" />
      <origin xyz="0 0 0" rpy="0 0 0" />
    </joint> -->

    <link
      name="${prefix}base_scan">
      <inertial>
        <origin
          xyz="-0.023581450658916 8.05046002083643E-09 0.00223779817490377"
          rpy="0 0 0" />
        <mass
          value="0.189335150961536" />
        <inertia
          ixx="9.4126569435462E-05"
          ixy="4.82701982803445E-11"
          ixz="-2.33945223821742E-06"
          iyy="0.000100748999349168"
          iyz="1.86083776093011E-13"
          izz="0.000140289739768048" />
      </inertial>
      <visual>
        <origin
          xyz="0 0 0"
          rpy="0 0 0" />
        <geometry>
          <mesh
            filename="package://two_wheel_mr/meshes/lidar_l.STL" />
        </geometry>
        <material
          name="">
          <color
            rgba="0.250980392156863 0.250980392156863 0.250980392156863 0.7" />
        </material>
      </visual>
      <collision>
        <origin
          xyz="0 0 0"
          rpy="0 0 0" />
        <geometry>
          <mesh
            filename="package://two_wheel_mr/meshes/lidar_l.STL" />
        </geometry>
      </collision>
    </link>
    <joint
      name="${prefix}lidar_joint"
      type="fixed">
      <origin
        xyz="0.39093 0 0.13197"
        rpy="0 0 0" />
      <parent
        link="${prefix}base_link" />
      <child
        link="${prefix}base_scan" />
      <axis
        xyz="0 0 0" />
    </joint>
    <link
      name="${prefix}left_wheel_link">
      <inertial>
        <origin
          xyz="-0.0457776666942068 -2.23112064812181E-06 2.22044604925031E-16"
          rpy="0 0 0" />
        <mass
          value="1.31100037203892" />
        <inertia
          ixx="0.00377530899740119"
          ixy="7.68621750778646E-08"
          ixz="9.64684500138943E-19"
          iyy="0.00241979899450848"
          iyz="-2.16840434497101E-19"
          izz="0.00241977565613022" />
      </inertial>
      <visual>
        <origin
          xyz="0 0 0"
          rpy="0 0 0" />
        <geometry>
          <mesh
            filename="package://two_wheel_mr/meshes/bc01_l.STL" />
        </geometry>
        <material
          name="">
          <color
            rgba="0.792156862745098 0.819607843137255 0.933333333333333 1" />
        </material>
      </visual>
      <collision>
        <origin
          xyz="0 0 0"
          rpy="0 0 0" />
        <geometry>
          <mesh
            filename="package://two_wheel_mr/meshes/bc01_l.STL" />
        </geometry>
      </collision>
    </link>
    <joint
      name="${prefix}left_wheel_joint"
      type="continuous">
      <origin
        xyz="0 0.1257 0.0385"
        rpy="2.6611 0 -1.5708" />
      <parent
        link="${prefix}base_link" />
      <child
        link="${prefix}left_wheel_link" />
      <axis
        xyz="1 0 0" />
    </joint>
    <link
      name="${prefix}right_wheel_link">
      <inertial>
        <origin
          xyz="0.0419723333057932 -2.23112064823283E-06 1.11022302462516E-16"
          rpy="0 0 0" />
        <mass
          value="1.31100037203892" />
        <inertia
          ixx="0.00377530899740119"
          ixy="7.68621750778817E-08"
          ixz="7.66604521934544E-19"
          iyy="0.00241979899450848"
          iyz="1.0842021724855E-19"
          izz="0.00241977565613022" />
      </inertial>
      <visual>
        <origin
          xyz="0 0 0"
          rpy="0 0 0" />
        <geometry>
          <mesh
            filename="package://two_wheel_mr/meshes/bc02_l.STL" />
        </geometry>
        <material
          name="">
          <color
            rgba="0.792156862745098 0.819607843137255 0.933333333333333 1" />
        </material>
      </visual>
      <collision>
        <origin
          xyz="0 0 0"
          rpy="0 0 0" />
        <geometry>
          <mesh
            filename="package://two_wheel_mr/meshes/bc02_l.STL" />
        </geometry>
      </collision>
    </link>
    <joint
      name="${prefix}right_wheel_joint"
      type="continuous">
      <origin
        xyz="0 -0.21345 0.0385"
        rpy="1.6958 0 1.5708" />
      <parent
        link="${prefix}base_link" />
      <child
        link="${prefix}right_wheel_link" />
      <axis
        xyz="1 0 0" />
    </joint>
    <link
      name="${prefix}caster1_link">
      <inertial>
        <origin
          xyz="0.00709216698228399 0.0478347934727232 -2.96831264567921E-07"
          rpy="0 0 0" />
        <mass
          value="0.0694916705945715" />
        <inertia
          ixx="0.00010569872478324"
          ixy="2.10345824058822E-05"
          ixz="9.45507984774347E-10"
          iyy="5.03454525775261E-05"
          iyz="-5.72929835921564E-10"
          izz="9.90224292840448E-05" />
      </inertial>
      <visual>
        <origin
          xyz="0 0 0"
          rpy="0 0 0" />
        <geometry>
          <mesh
            filename="package://two_wheel_mr/meshes/gbp01_l.STL" />
        </geometry>
        <material
          name="">
          <color
            rgba="0.250980392156863 0.250980392156863 0.250980392156863 1" />
        </material>
      </visual>
      <collision>
        <origin
          xyz="0 0 0"
          rpy="0 0 0" />
        <geometry>
          <mesh
            filename="package://two_wheel_mr/meshes/gbp01_l.STL" />
        </geometry>
      </collision>
    </link>
    <joint
      name="${prefix}caster1_joint"
      type="fixed">
      <origin
        xyz="0.31539 0.16395 -0.019"
        rpy="1.5708 0 1.3562" />
      <parent
        link="${prefix}base_link" />
      <child
        link="${prefix}caster1_link" />
      <axis
        xyz="0 1 0" />
    </joint>
    <link
      name="${prefix}caster_wheel1_link">
      <inertial>
        <origin
          xyz="5.55111512312578E-16 3.33066907387547E-16 5.55111512312578E-17"
          rpy="0 0 0" />
        <mass
          value="0.152173788807328" />
        <inertia
          ixx="6.29515545648915E-05"
          ixy="-1.0249098661777E-19"
          ixz="-5.26086869583726E-22"
          iyy="0.000116211605751744"
          iyz="1.05879118406788E-22"
          izz="6.29515545648916E-05" />
      </inertial>
      <visual>
        <origin
          xyz="0 0 0"
          rpy="0 0 0" />
        <geometry>
          <mesh
            filename="package://two_wheel_mr/meshes/bp01_l.STL" />
        </geometry>
        <material
          name="">
          <color
            rgba="1 0.647058823529412 0.270588235294118 1" />
        </material>
      </visual>
      <collision>
        <origin
          xyz="0 0 0"
          rpy="0 0 0" />
        <geometry>
          <mesh
            filename="package://two_wheel_mr/meshes/bp01_l.STL" />
        </geometry>
      </collision>
    </link>
    <joint
      name="${prefix}caster_wheel1_joint"
      type="fixed">
      <origin
        xyz="0.02 0.015 0"
        rpy="-1.5708 0 -0.010909" />
      <parent
        link="${prefix}caster1_link" />
      <child
        link="${prefix}caster_wheel1_link" />
      <axis
        xyz="0 1 0" />
    </joint>
    <link
      name="${prefix}caster2_link">
      <inertial>
        <origin
          xyz="0.00709207307857418 0.0478347566587795 -5.30493133976684E-07"
          rpy="0 0 0" />
        <mass
          value="0.0694918485906587" />
        <inertia
          ixx="0.000105698752292165"
          ixy="2.10345662757272E-05"
          ixz="8.6310744313464E-10"
          iyy="5.03454861728689E-05"
          iyz="-5.70855965874165E-10"
          izz="9.90224068615156E-05" />
      </inertial>
      <visual>
        <origin
          xyz="0 0 0"
          rpy="0 0 0" />
        <geometry>
          <mesh
            filename="package://two_wheel_mr/meshes/gbp02_l.STL" />
        </geometry>
        <material
          name="">
          <color
            rgba="0.250980392156863 0.250980392156863 0.250980392156863 1" />
        </material>
      </visual>
      <collision>
        <origin
          xyz="0 0 0"
          rpy="0 0 0" />
        <geometry>
          <mesh
            filename="package://two_wheel_mr/meshes/gbp02_l.STL" />
        </geometry>
      </collision>
    </link>
    <joint
      name="${prefix}caster2_joint"
      type="fixed">
      <origin
        xyz="0.31539 -0.16395 -0.019"
        rpy="1.5708 0 1.5708" />
      <parent
        link="${prefix}base_link" />
      <child
        link="${prefix}caster2_link" />
      <axis
        xyz="0 1 0" />
    </joint>
    <link
      name="${prefix}caster_wheel2_link">
      <inertial>
        <origin
          xyz="0 -1.11022302462516E-16 5.55111512312578E-17"
          rpy="0 0 0" />
        <mass
          value="0.152173788807328" />
        <inertia
          ixx="6.29515545648916E-05"
          ixy="-9.56945725483922E-38"
          ixz="-1.17168733020458E-38"
          iyy="0.000116211605751744"
          iyz="-2.76804456158444E-36"
          izz="6.29515545648916E-05" />
      </inertial>
      <visual>
        <origin
          xyz="0 0 0"
          rpy="0 0 0" />
        <geometry>
          <mesh
            filename="package://two_wheel_mr/meshes/bp02_l.STL" />
        </geometry>
        <material
          name="">
          <color
            rgba="1 0.647058823529412 0.270588235294118 1" />
        </material>
      </visual>
      <collision>
        <origin
          xyz="0 0 0"
          rpy="0 0 0" />
        <geometry>
          <mesh
            filename="package://two_wheel_mr/meshes/bp02_l.STL" />
        </geometry>
      </collision>
    </link>
    <joint
      name="${prefix}caster_wheel2_joint"
      type="fixed">
      <origin
        xyz="0.02 0.015 0"
        rpy="-1.5708 0 0" />
      <parent
        link="${prefix}caster2_link" />
      <child
        link="${prefix}caster_wheel2_link" />
      <axis
        xyz="0 1 0" />
    </joint>
    <link
      name="${prefix}caster3_link">
      <inertial>
        <origin
          xyz="0.0070920730785744 0.0478347566587794 -5.30493133588106E-07"
          rpy="0 0 0" />
        <mass
          value="0.0694918485906584" />
        <inertia
          ixx="0.000105698752292165"
          ixy="2.1034566275727E-05"
          ixz="8.63107442972788E-10"
          iyy="5.03454861728694E-05"
          iyz="-5.70855965405794E-10"
          izz="9.90224068615163E-05" />
      </inertial>
      <visual>
        <origin
          xyz="0 0 0"
          rpy="0 0 0" />
        <geometry>
          <mesh
            filename="package://two_wheel_mr/meshes/gbp03_l.STL" />
        </geometry>
        <material
          name="">
          <color
            rgba="0.250980392156863 0.250980392156863 0.250980392156863 1" />
        </material>
      </visual>
      <collision>
        <origin
          xyz="0 0 0"
          rpy="0 0 0" />
        <geometry>
          <mesh
            filename="package://two_wheel_mr/meshes/gbp03_l.STL" />
        </geometry>
      </collision>
    </link>
    <joint
      name="${prefix}caster3_joint"
      type="fixed">
      <origin
        xyz="-0.31539 0.16395 -0.019"
        rpy="1.5708 0 1.5708" />
      <parent
        link="${prefix}base_link" />
      <child
        link="${prefix}caster3_link" />
      <axis
        xyz="0 1 0" />
    </joint>
    <link
      name="${prefix}caster_wheel3_link">
      <inertial>
        <origin
          xyz="5.55111512312578E-17 -5.55111512312578E-17 5.55111512312578E-17"
          rpy="0 0 0" />
        <mass
          value="0.152173788807328" />
        <inertia
          ixx="6.29515545648914E-05"
          ixy="-9.56945725483922E-38"
          ixz="-1.17168733020459E-38"
          iyy="0.000116211605751743"
          iyz="-5.357349065892E-39"
          izz="6.29515545648914E-05" />
      </inertial>
      <visual>
        <origin
          xyz="0 0 0"
          rpy="0 0 0" />
        <geometry>
          <mesh
            filename="package://two_wheel_mr/meshes/bp03_l.STL" />
        </geometry>
        <material
          name="">
          <color
            rgba="1 0.647058823529412 0.270588235294118 1" />
        </material>
      </visual>
      <collision>
        <origin
          xyz="0 0 0"
          rpy="0 0 0" />
        <geometry>
          <mesh
            filename="package://two_wheel_mr/meshes/bp03_l.STL" />
        </geometry>
      </collision>
    </link>
    <joint
      name="${prefix}caster_wheel3_joint"
      type="fixed">
      <origin
        xyz="0.02 0.015 0"
        rpy="-1.5708 0 0" />
      <parent
        link="${prefix}caster3_link" />
      <child
        link="${prefix}caster_wheel3_link" />
      <axis
        xyz="0 1 0" />
    </joint>
    <link
      name="${prefix}caster4_link">
      <inertial>
        <origin
          xyz="0.0070920730785744 0.0478347566587793 -5.30493133976684E-07"
          rpy="0 0 0" />
        <mass
          value="0.0694918485906587" />
        <inertia
          ixx="0.000105698752292165"
          ixy="2.10345662757271E-05"
          ixz="8.63107443166208E-10"
          iyy="5.03454861728693E-05"
          iyz="-5.70855965551857E-10"
          izz="9.90224068615163E-05" />
      </inertial>
      <visual>
        <origin
          xyz="0 0 0"
          rpy="0 0 0" />
        <geometry>
          <mesh
            filename="package://two_wheel_mr/meshes/gbp04_l.STL" />
        </geometry>
        <material
          name="">
          <color
            rgba="0.250980392156863 0.250980392156863 0.250980392156863 1" />
        </material>
      </visual>
      <collision>
        <origin
          xyz="0 0 0"
          rpy="0 0 0" />
        <geometry>
          <mesh
            filename="package://two_wheel_mr/meshes/gbp04_l.STL" />
        </geometry>
      </collision>
    </link>
    <joint
      name="${prefix}caster4_joint"
      type="fixed">
      <origin
        xyz="-0.31539 -0.16395 -0.019"
        rpy="1.5708 0 1.5708" />
      <parent
        link="${prefix}base_link" />
      <child
        link="${prefix}caster4_link" />
      <axis
        xyz="0 1 0" />
    </joint>
    <link
      name="${prefix}caster_wheel4_link">
      <inertial>
        <origin
          xyz="0 0 5.55111512312578E-17"
          rpy="0 0 0" />
        <mass
          value="0.152173788807328" />
        <inertia
          ixx="6.29515545648914E-05"
          ixy="-9.56945725483922E-38"
          ixz="-1.17168733020459E-38"
          iyy="0.000116211605751743"
          iyz="-5.357349065892E-39"
          izz="6.29515545648914E-05" />
      </inertial>
      <visual>
        <origin
          xyz="0 0 0"
          rpy="0 0 0" />
        <geometry>
          <mesh
            filename="package://two_wheel_mr/meshes/bp04_l.STL" />
        </geometry>
        <material
          name="">
          <color
            rgba="1 0.647058823529412 0.270588235294118 1" />
        </material>
      </visual>
      <collision>
        <origin
          xyz="0 0 0"
          rpy="0 0 0" />
        <geometry>
          <mesh
            filename="package://two_wheel_mr/meshes/bp04_l.STL" />
        </geometry>
      </collision>
    </link>
    <joint
      name="${prefix}caster_wheel4_joint"
      type="fixed">
      <origin
        xyz="0.02 0.015 0"
        rpy="-1.5708 0 0" />
      <parent
        link="${prefix}caster4_link" />
      <child
        link="${prefix}caster_wheel4_link" />
      <axis
        xyz="0 1 0" />
    </joint>

    <joint
      name="${prefix}arm_base_joint"
      type="fixed">
      <origin
        xyz="0 0 0.175"
        rpy="0 0 0" />
      <parent
        link="${prefix}base_link" />
      <child
        link="${prefix}arm_base_link" />
      <axis
        xyz="0 -1 0" />
      <limit
        lower="0"
        upper="0"
        effort="0"
        velocity="0" />
    </joint>

    <link
      name="${prefix}arm_base_link">
      <inertial>
        <origin
          xyz="-0.00031896 -0.00029673 0.042463"
          rpy="0 0 0" />
        <mass
          value="1.6185" />
        <inertia
          ixx="0.0030836"
          ixy="1.5354E-05"
          ixz="-1.9315E-05"
          iyy="0.0030825"
          iyz="-1.7918E-05"
          izz="0.0045209" />
      </inertial>
      <visual>
        <origin
          xyz="0 0 0"
          rpy="0 0 0" />
        <geometry>
          <mesh
            filename="package://fairino_description/meshes/fairino5_v6/base_link.STL" />
        </geometry>
        <material
          name="${prefix}">
          <color
            rgba="0.89804 0.91765 0.92941 1" />
        </material>
      </visual>
      <collision>
        <origin
          xyz="0 0 0"
          rpy="0 0 0" />
        <geometry>
          <mesh
            filename="package://fairino_description/meshes/fairino5_v6/base_link.STL" />
        </geometry>
      </collision>
    </link>
    <link
      name="${prefix}shoulder_link">
      <inertial>
        <origin
          xyz="5.0029E-07 -0.0040922 0.14629"
          rpy="0 0 0" />
        <mass
          value="4.3771" />
        <inertia
          ixx="0.010731"
          ixy="-8.0587E-09"
          ixz="-3.6773E-08"
          iyy="0.010408"
          iyz="0.00012853"
          izz="0.0081793" />
      </inertial>
      <visual>
        <origin
          xyz="0 0 0"
          rpy="0 0 0" />
        <geometry>
          <mesh
            filename="package://fairino_description/meshes/fairino5_v6/shoulder_link.STL" />
        </geometry>
        <material
          name="${prefix}">
          <color
            rgba="0.89804 0.91765 0.92941 1" />
        </material>
      </visual>
      <collision>
        <origin
          xyz="0 0 0"
          rpy="0 0 0" />
        <geometry>
          <mesh
            filename="package://fairino_description/meshes/fairino5_v6/shoulder_link.STL" />
        </geometry>
      </collision>
    </link>
    <joint
      name="${prefix}j1"
      type="revolute">
      <origin
        xyz="0 0 0"
        rpy="0 0 0" />
      <parent
        link="${prefix}arm_base_link" />
      <child
        link="${prefix}shoulder_link" />
      <axis
        xyz="0 0 1" />
      <limit
        lower="-3.0543"
        upper="3.0543"
        effort="150"
        velocity="3.15" />
      <calibration
        rising="0"
        falling="0" />
      <dynamics
        damping="0"
        friction="0" />
      <safety_controller
        soft_lower_limit="-3.0543"
        soft_upper_limit="3.0543"
        k_position="15"
        k_velocity="10" />
    </joint>
    <link
      name="${prefix}upperarm_link">
      <inertial>
        <origin
          xyz="-0.2125 -5.7643E-09 0.1346"
          rpy="0 0 0" />
        <mass
          value="14.458" />
        <inertia
          ixx="0.028392"
          ixy="-1.337E-07"
          ixz="-3.9895E-09"
          iyy="0.4559"
          iyz="4.214E-08"
          izz="0.44974" />
      </inertial>
      <visual>
        <origin
          xyz="0 0 0"
          rpy="0 0 0" />
        <geometry>
          <mesh
            filename="package://fairino_description/meshes/fairino5_v6/upperarm_link.STL" />
        </geometry>
        <material
          name="${prefix}">
          <color
            rgba="0.89804 0.91765 0.92941 1" />
        </material>
      </visual>
      <collision>
        <origin
          xyz="0 0 0"
          rpy="0 0 0" />
        <geometry>
          <mesh
            filename="package://fairino_description/meshes/fairino5_v6/upperarm_link.STL" />
        </geometry>
      </collision>
    </link>
    <joint
      name="${prefix}j2"
      type="revolute">
      <origin
        xyz="0 0 0.152"
        rpy="1.5708 0 0" />
      <parent
        link="${prefix}shoulder_link" />
      <child
        link="${prefix}upperarm_link" />
      <axis
        xyz="0 0 1" />
      <limit
        lower="-4.6251"
        upper="1.4835"
        effort="150"
        velocity="3.15" />
      <calibration
        rising="0"
        falling="0" />
      <dynamics
        damping="0"
        friction="0" />
      <safety_controller
        soft_lower_limit="-4.6251"
        soft_upper_limit="1.4835"
        k_position="15"
        k_velocity="10" />
    </joint>
    <link
      name="${prefix}forearm_link">
      <inertial>
        <origin
          xyz="-0.18793 -8.4503E-07 0.0066357"
          rpy="0 0 0" />
        <mass
          value="7.6737" />
        <inertia
          ixx="0.0085096"
          ixy="2.1613E-06"
          ixz="-0.0068678"
          iyy="0.16971"
          iyz="3.7086E-08"
          izz="0.16854" />
      </inertial>
      <visual>
        <origin
          xyz="0 0 0"
          rpy="0 0 0" />
        <geometry>
          <mesh
            filename="package://fairino_description/meshes/fairino5_v6/forearm_link.STL" />
        </geometry>
        <material
          name="${prefix}">
          <color
            rgba="0.89804 0.91765 0.92941 1" />
        </material>
      </visual>
      <collision>
        <origin
          xyz="0 0 0"
          rpy="0 0 0" />
        <geometry>
          <mesh
            filename="package://fairino_description/meshes/fairino5_v6/forearm_link.STL" />
        </geometry>
      </collision>
    </link>
    <joint
      name="${prefix}j3"
      type="revolute">
      <origin
        xyz="-0.425 0 0"
        rpy="0 0 0" />
      <parent
        link="${prefix}upperarm_link" />
      <child
        link="${prefix}forearm_link" />
      <axis
        xyz="0 0 1" />
      <limit
        lower="-2.8274"
        upper="2.8274"
        effort="150"
        velocity="3.15" />
      <calibration
        rising="0"
        falling="0" />
      <dynamics
        damping="0"
        friction="0" />
      <safety_controller
        soft_lower_limit="-2.8274"
        soft_upper_limit="2.8274"
        k_position="15"
        k_velocity="10" />
    </joint>
    <link
      name="${prefix}wrist1_link">
      <inertial>
        <origin
          xyz="4.98E-07 -0.003754 0.097155"
          rpy="0 0 0" />
        <mass
          value="1.6266" />
        <inertia
          ixx="0.00216"
          ixy="4.888E-09"
          ixz="3.1528E-08"
          iyy="0.0015455"
          iyz="3.7678E-05"
          izz="0.0019902" />
      </inertial>
      <visual>
        <origin
          xyz="0 0 0"
          rpy="0 0 0" />
        <geometry>
          <mesh
            filename="package://fairino_description/meshes/fairino5_v6/wrist1_link.STL" />
        </geometry>
        <material
          name="${prefix}">
          <color
            rgba="0.89804 0.91765 0.92941 1" />
        </material>
      </visual>
      <collision>
        <origin
          xyz="0 0 0"
          rpy="0 0 0" />
        <geometry>
          <mesh
            filename="package://fairino_description/meshes/fairino5_v6/wrist1_link.STL" />
        </geometry>
      </collision>
    </link>
    <joint
      name="${prefix}j4"
      type="revolute">
      <origin
        xyz="-0.39501 0 0"
        rpy="0 0 0" />
      <parent
        link="${prefix}forearm_link" />
      <child
        link="${prefix}wrist1_link" />
      <axis
        xyz="0 0 1" />
      <limit
        lower="-4.6251"
        upper="1.4835"
        effort="28"
        velocity="3.2" />
      <calibration
        rising="0"
        falling="0" />
      <dynamics
        damping="0"
        friction="0" />
      <safety_controller
        soft_lower_limit="-4.6251"
        soft_upper_limit="1.4835"
        k_position="15"
        k_velocity="10" />
    </joint>
    <link
      name="${prefix}wrist2_link">
      <inertial>
        <origin
          xyz="-4.5588E-07 0.0038617 0.098257"
          rpy="0 0 0" />
        <mass
          value="1.5812" />
        <inertia
          ixx="0.0020612"
          ixy="8.7064E-09"
          ixz="-3.4742E-08"
          iyy="0.0014477"
          iyz="-2.8534E-05"
          izz="0.0019573" />
      </inertial>
      <visual>
        <origin
          xyz="0 0 0"
          rpy="0 0 0" />
        <geometry>
          <mesh
            filename="package://fairino_description/meshes/fairino5_v6/wrist2_link.STL" />
        </geometry>
        <material
          name="${prefix}">
          <color
            rgba="0.89804 0.91765 0.92941 1" />
        </material>
      </visual>
      <collision>
        <origins
          xyz="0 0 0"
          rpy="0 0 0" />
        <geometry>
          <mesh
            filename="package://fairino_description/meshes/fairino5_v6/wrist2_link.STL" />
        </geometry>
      </collision>
    </link>
    <joint
      name="${prefix}j5"
      type="revolute">
      <origin
        xyz="0 0 0.1021"
        rpy="1.5708 0 0" />
      <parent
        link="${prefix}wrist1_link" />
      <child
        link="${prefix}wrist2_link" />
      <axis
        xyz="0 0 1" />
      <limit
        lower="-3.0543"
        upper="3.0543"
        effort="28"
        velocity="3.2" />
      <calibration
        rising="0"
        falling="0" />
      <dynamics
        damping="0"
        friction="0" />
      <safety_controller
        soft_lower_limit="-3.0543"
        soft_upper_limit="3.0543"
        k_position="15"
        k_velocity="10" />
    </joint>
    <link
      name="${prefix}wrist3_link">
      <inertial>
        <origin
          xyz="7.7496E-05 1.7751E-05 0.076122"
          rpy="0 0 0" />
        <mass
          value="0.52542" />
        <inertia
          ixx="0.00027721"
          ixy="-1.8677E-09"
          ixz="-1.188E-07"
          iyy="0.00027839"
          iyz="2.2607E-07"
          izz="0.00041605" />
      </inertial>
      <visual>
        <origin
          xyz="0 0 0"
          rpy="0 0 0" />
        <geometry>
          <mesh
            filename="package://fairino_description/meshes/fairino5_v6/wrist3_link.STL" />
        </geometry>
        <material
          name="${prefix}">
          <color
            rgba="0.89804 0.91765 0.92941 1" />
        </material>
      </visual>
      <collision>
        <origin
          xyz="0 0 0"
          rpy="0 0 0" />
        <geometry>
          <mesh
            filename="package://fairino_description/meshes/fairino5_v6/wrist3_link.STL" />
        </geometry>
      </collision>
    </link>
    <joint
      name="${prefix}j6"
      type="revolute">
      <origin
        xyz="0 0 0.102"
        rpy="-1.5708 0 0" />
      <parent
        link="${prefix}wrist2_link" />
      <child
        link="${prefix}wrist3_link" />
      <axis
        xyz="0 0 1" />
      <limit
        lower="-3.0543"
        upper="3.0543"
        effort="28"
        velocity="3.2" />
      <calibration
        rising="0"
        falling="0" />
      <dynamics
        damping="0"
        friction="0" />
      <safety_controller
        soft_lower_limit="-3.0543"
        soft_upper_limit="3.0543"
        k_position="15"
        k_velocity="10" />
    </joint>
  </xacro:macro>
</robot>
